Workbook

Sheet Display Points
A1: Teams | B1: Points
A2: Kurt (Austria, Czech, Italy, New Zealand, South Korea) | B2: =Events!U95 -> 42
A3: Neigum (Czech, Estonia, Finland, Italy, Latvia, United States) | B3: =Events!Y95 -> 41
A4: Ian (Japan, Italy, Netherlands, Argentina) | B4: =Events!AI95 -> 36
A5: Mansell 2 (Netherlands, France, Italy, AIN) | B5: =Events!N95 -> 29
A6: Colby (Swiss, Jamaica, Italy, Netherlands) | B6: =Events!W95 -> 38
A7: Cory (Czech, Finland, Norway, Poland, Slovakia) | B7: =Events!O95 -> 37
A8: Grace (USA, Sweden, Great Britain, Czech) | B8: =Events!AH95 -> 35
A9: Josh (Belgium, Estonia, AIN, Norway, Poland, Slovenia) | B9: =Events!Q95 -> 37
A10: Bill (Lithuania, Norway, South Korea, Ukraine) | B10: =Events!S95 -> 32
A11: Rhett (Norway, Belgium, Estonia, South Korea) | B11: =Events!R95 -> 33
A12: Evan 2 (Norway, South Korea, Hungary) | B12: =Events!AF95 -> 32
A13: Richard (Australia, Austria, Belgium, France, Finland, Romania) | B13: =Events!X95 -> 23
A14: Evan 1 (Sweden, Swiss, Latvia, Poland) | B14: =Events!AE95 -> 34
A15: Huebner (Austria, China, Czech, South Korea, Spain) | B15: =Events!AB95 -> 25
A16: Pam 2 (Canada, Czech, Ukraine, US) | B16: =Events!AD95 -> 25
A17: Tiffany (Canada, Sweden, Finland, Slovakia, Poland) | B17: =Events!AG95 -> 21
A18: Jonah (Germany, Sweden) | B18: =Events!AA95 -> 28
A19: Pam 1 (Germany, Sweden) | B19: =Events!AC95 -> 28
A20: Amanda (Canada, Czech, Netherlands, Slovenia, Ukraine) | B20: =Events!P95 -> 19
A21: Ryley (Canada, USA, Slovakia, Poland, Latvia) | B21: =Events!V95 -> 24
A22: Fader (Canada, Finland, Netherlands, Latvia, Estonia, Slovakia) | B22: =Events!T95 -> 12
A23: Mansell 1 (Germany, Netherlands) | B23: =Events!M95 -> 19
A24: Wagner (Estonia, Poland, Germany, China) | B24: =Events!Z95 -> 19

Sheet Events
A1: countries | B1: countries | C1: match | D1: 2022 Gold | E1: 2022 Silver | F1: 2022 Bronze | G1: Cost | H1: Number of Events | I1: 2026 Gold | J1: 2026 Silver | K1: 2026 Bronze | L1: Total Points | M1: Kevin Mansell 1 | N1: Kevin Mansell 2 | O1: Cory Brace | P1: Amanda | Q1: Josh | R1: Rhett | S1: Bill | T1: Fader | U1: Kurt Heidel | V1: Ryley | W1: Colby | X1: Richard | Y1: Neigem | Z1: Wagner | AA1: Jonah | AB1: Huebner | AC1: Pam1 | AD1: Pam2 | AE1: Evan1 | AF1: Evan2 | AG1: Tiffany | AH1: Grace | AI1: Ian
A2: Albania (2) | B2: Albania | C2: =MATCH(Events!B2,'Medal Count'!C:C,0) -> 3 | G2: =IF(SUM((D2*3)+(E2*2)+(F2*1))>0,SUM((D2*3)+(E2*2)+(F2*1)),3) -> 3 | H2: 2 | I2: {=INDEX('Medal Count'!D:D,Events!$C2)} -> 0 | J2: {=INDEX('Medal Count'!E:E,Events!$C2)} -> 0 | K2: {=INDEX('Medal Count'!F:F,Events!$C2)} -> 0 | L2: =(I2*3*2)+(J2*2*2)+(K2*1*2) -> 0
A3: Andorra (6) | B3: Andorra | C3: =MATCH(Events!B3,'Medal Count'!C:C,0) -> 4 | G3: =IF(SUM((D3*3)+(E3*2)+(F3*1))>0,SUM((D3*3)+(E3*2)+(F3*1)),3) -> 3 | H3: 6 | I3: {=INDEX('Medal Count'!D:D,Events!$C3)} -> 0 | J3: {=INDEX('Medal Count'!E:E,Events!$C3)} -> 0 | K3: {=INDEX('Medal Count'!F:F,Events!$C3)} -> 0 | L3: =(I3*3*2)+(J3*2*2)+(K3*1*2) -> 0
A4: Argentina (6) | B4: Argentina | C4: =MATCH(Events!B4,'Medal Count'!C:C,0) -> 5 | G4: =IF(SUM((D4*3)+(E4*2)+(F4*1))>0,SUM((D4*3)+(E4*2)+(F4*1)),3) -> 3 | H4: 6 | I4: {=INDEX('Medal Count'!D:D,Events!$C4)} -> 0 | J4: {=INDEX('Medal Count'!E:E,Events!$C4)} -> 0 | K4: {=INDEX('Medal Count'!F:F,Events!$C4)} -> 0 | L4: =(I4*3*2)+(J4*2*2)+(K4*1*2) -> 0 | AI4: 1
A5: Armenia (6) | B5: Armenia | C5: =MATCH(Events!B5,'Medal Count'!C:C,0) -> 6 | G5: =IF(SUM((D5*3)+(E5*2)+(F5*1))>0,SUM((D5*3)+(E5*2)+(F5*1)),3) -> 3 | H5: 6 | I5: {=INDEX('Medal Count'!D:D,Events!$C5)} -> 0 | J5: {=INDEX('Medal Count'!E:E,Events!$C5)} -> 0 | K5: {=INDEX('Medal Count'!F:F,Events!$C5)} -> 0 | L5: =(I5*3*2)+(J5*2*2)+(K5*1*2) -> 0
A6: Australia (17) | B6: Australia | C6: =MATCH(Events!B6,'Medal Count'!C:C,0) -> 7 | D6: 1 | E6: 2 | F6: 1 | G6: =IF(SUM((D6*3)+(E6*2)+(F6*1))>0,SUM((D6*3)+(E6*2)+(F6*1)),3) -> 8 | H6: 17 | I6: {=INDEX('Medal Count'!D:D,Events!$C6)} -> 0 | J6: {=INDEX('Medal Count'!E:E,Events!$C6)} -> 0 | K6: {=INDEX('Medal Count'!F:F,Events!$C6)} -> 0 | L6: =SUM((I6*3)+(J6*2)+(K6*1)) -> 0 | X6: 1
A7: Austria (32) | B7: Austria | C7: =MATCH(Events!B7,'Medal Count'!C:C,0) -> 8 | D7: 7 | E7: 7 | F7: 4 | G7: =IF(SUM((D7*3)+(E7*2)+(F7*1))>0,SUM((D7*3)+(E7*2)+(F7*1)),3) -> 39 | H7: 32 | I7: {=INDEX('Medal Count'!D:D,Events!$C7)} -> 2 | J7: {=INDEX('Medal Count'!E:E,Events!$C7)} -> 4 | K7: {=INDEX('Medal Count'!F:F,Events!$C7)} -> 0 | L7: =SUM((I7*3)+(J7*2)+(K7*1)) -> 14 | U7: 1 | X7: 1 | AB7: 1
A8: Azerbaijan (2) | B8: Azerbaijan | C8: =MATCH(Events!B8,'Medal Count'!C:C,0) -> 9 | G8: =IF(SUM((D8*3)+(E8*2)+(F8*1))>0,SUM((D8*3)+(E8*2)+(F8*1)),3) -> 3 | H8: 2 | I8: {=INDEX('Medal Count'!D:D,Events!$C8)} -> 0 | J8: {=INDEX('Medal Count'!E:E,Events!$C8)} -> 0 | K8: {=INDEX('Medal Count'!F:F,Events!$C8)} -> 0 | L8: =(I8*3*2)+(J8*2*2)+(K8*1*2) -> 0
A9: Belgium (26) | B9: Belgium | C9: =MATCH(Events!B9,'Medal Count'!C:C,0) -> 10 | D9: 1 | E9: 0 | F9: 1 | G9: =IF(SUM((D9*3)+(E9*2)+(F9*1))>0,SUM((D9*3)+(E9*2)+(F9*1)),3) -> 4 | H9: 26 | I9: {=INDEX('Medal Count'!D:D,Events!$C9)} -> 0 | J9: {=INDEX('Medal Count'!E:E,Events!$C9)} -> 0 | K9: {=INDEX('Medal Count'!F:F,Events!$C9)} -> 1 | L9: =SUM((I9*3)+(J9*2)+(K9*1)) -> 1 | Q9: 1 | R9: 1 | X9: 1
A10: Benin (1) | B10: Benin | C10: =MATCH(Events!B10,'Medal Count'!C:C,0) -> 11 | G10: =IF(SUM((D10*3)+(E10*2)+(F10*1))>0,SUM((D10*3)+(E10*2)+(F10*1)),3) -> 3 | H10: 1 | I10: {=INDEX('Medal Count'!D:D,Events!$C10)} -> 0 | J10: {=INDEX('Medal Count'!E:E,Events!$C10)} -> 0 | K10: {=INDEX('Medal Count'!F:F,Events!$C10)} -> 0 | L10: =(I10*3*2)+(J10*2*2)+(K10*1*2) -> 0
A11: Bolivia (1) | B11: Bolivia | C11: =MATCH(Events!B11,'Medal Count'!C:C,0) -> 12 | G11: =IF(SUM((D11*3)+(E11*2)+(F11*1))>0,SUM((D11*3)+(E11*2)+(F11*1)),3) -> 3 | H11: 1 | I11: {=INDEX('Medal Count'!D:D,Events!$C11)} -> 0 | J11: {=INDEX('Medal Count'!E:E,Events!$C11)} -> 0 | K11: {=INDEX('Medal Count'!F:F,Events!$C11)} -> 0 | L11: =(I11*3*2)+(J11*2*2)+(K11*1*2) -> 0
A12: Bosnia and Herzegovina (4) | B12: Bosnia and Herzegovina | C12: =MATCH(Events!B12,'Medal Count'!C:C,0) -> 13 | G12: =IF(SUM((D12*3)+(E12*2)+(F12*1))>0,SUM((D12*3)+(E12*2)+(F12*1)),3) -> 3 | H12: 4 | I12: {=INDEX('Medal Count'!D:D,Events!$C12)} -> 0 | J12: {=INDEX('Medal Count'!E:E,Events!$C12)} -> 0 | K12: {=INDEX('Medal Count'!F:F,Events!$C12)} -> 0 | L12: =(I12*3*2)+(J12*2*2)+(K12*1*2) -> 0
A13: Brazil (5) | B13: Brazil | C13: =MATCH(Events!B13,'Medal Count'!C:C,0) -> 14 | G13: =IF(SUM((D13*3)+(E13*2)+(F13*1))>0,SUM((D13*3)+(E13*2)+(F13*1)),3) -> 3 | H13: 5 | I13: {=INDEX('Medal Count'!D:D,Events!$C13)} -> 0 | J13: {=INDEX('Medal Count'!E:E,Events!$C13)} -> 0 | K13: {=INDEX('Medal Count'!F:F,Events!$C13)} -> 0 | L13: =(I13*3*2)+(J13*2*2)+(K13*1*2) -> 0
A14: Bulgaria (14) | B14: Bulgaria | C14: =MATCH(Events!B14,'Medal Count'!C:C,0) -> 15 | G14: =IF(SUM((D14*3)+(E14*2)+(F14*1))>0,SUM((D14*3)+(E14*2)+(F14*1)),3) -> 3 | H14: 14 | I14: {=INDEX('Medal Count'!D:D,Events!$C14)} -> 0 | J14: {=INDEX('Medal Count'!E:E,Events!$C14)} -> 0 | K14: {=INDEX('Medal Count'!F:F,Events!$C14)} -> 1 | L14: =(I14*3*2)+(J14*2*2)+(K14*1*2) -> 2
A15: Canada (117) | B15: Canada | C15: =MATCH(Events!B15,'Medal Count'!C:C,0) -> 16 | D15: 4 | E15: 8 | F15: 14 | G15: =IF(SUM((D15*3)+(E15*2)+(F15*1))>0,SUM((D15*3)+(E15*2)+(F15*1)),3) -> 42 | H15: 117 | I15: {=INDEX('Medal Count'!D:D,Events!$C15)} -> 0 | J15: {=INDEX('Medal Count'!E:E,Events!$C15)} -> 1 | K15: {=INDEX('Medal Count'!F:F,Events!$C15)} -> 2 | L15: =SUM((I15*3)+(J15*2)+(K15*1)) -> 4 | P15: 1 | T15: 1 | V15: 1 | AD15: 1 | AG15: 1
A16: Chile (3) | B16: Chile | C16: =MATCH(Events!B16,'Medal Count'!C:C,0) -> 17 | G16: =IF(SUM((D16*3)+(E16*2)+(F16*1))>0,SUM((D16*3)+(E16*2)+(F16*1)),3) -> 3 | H16: 3 | I16: {=INDEX('Medal Count'!D:D,Events!$C16)} -> 0 | J16: {=INDEX('Medal Count'!E:E,Events!$C16)} -> 0 | K16: {=INDEX('Medal Count'!F:F,Events!$C16)} -> 0 | L16: =(I16*3*2)+(J16*2*2)+(K16*1*2) -> 0
A17: China (51) | B17: China | C17: =MATCH(Events!B17,'Medal Count'!C:C,0) -> 18 | D17: 9 | E17: 4 | F17: 2 | G17: =IF(SUM((D17*3)+(E17*2)+(F17*1))>0,SUM((D17*3)+(E17*2)+(F17*1)),3) -> 37 | H17: 51 | I17: {=INDEX('Medal Count'!D:D,Events!$C17)} -> 0 | J17: {=INDEX('Medal Count'!E:E,Events!$C17)} -> 1 | K17: {=INDEX('Medal Count'!F:F,Events!$C17)} -> 1 | L17: =SUM((I17*3)+(J17*2)+(K17*1)) -> 3 | Z17: 1 | AB17: 1
A18: Colombia (1) | B18: Colombia | C18: =MATCH(Events!B18,'Medal Count'!C:C,0) -> 20 | G18: =IF(SUM((D18*3)+(E18*2)+(F18*1))>0,SUM((D18*3)+(E18*2)+(F18*1)),3) -> 3 | H18: 1 | I18: {=INDEX('Medal Count'!D:D,Events!$C18)} -> 0 | J18: {=INDEX('Medal Count'!E:E,Events!$C18)} -> 0 | K18: {=INDEX('Medal Count'!F:F,Events!$C18)} -> 0 | L18: =(I18*3*2)+(J18*2*2)+(K18*1*2) -> 0
A19: Croatia (7) | B19: Croatia | C19: =MATCH(Events!B19,'Medal Count'!C:C,0) -> 21 | G19: =IF(SUM((D19*3)+(E19*2)+(F19*1))>0,SUM((D19*3)+(E19*2)+(F19*1)),3) -> 3 | H19: 7 | I19: {=INDEX('Medal Count'!D:D,Events!$C19)} -> 0 | J19: {=INDEX('Medal Count'!E:E,Events!$C19)} -> 0 | K19: {=INDEX('Medal Count'!F:F,Events!$C19)} -> 0 | L19: =(I19*3*2)+(J19*2*2)+(K19*1*2) -> 0
A20: Cyprus (2) | B20: Cyprus | C20: =MATCH(Events!B20,'Medal Count'!C:C,0) -> 22 | G20: =IF(SUM((D20*3)+(E20*2)+(F20*1))>0,SUM((D20*3)+(E20*2)+(F20*1)),3) -> 3 | H20: 2 | I20: {=INDEX('Medal Count'!D:D,Events!$C20)} -> 0 | J20: {=INDEX('Medal Count'!E:E,Events!$C20)} -> 0 | K20: {=INDEX('Medal Count'!F:F,Events!$C20)} -> 0 | L20: =(I20*3*2)+(J20*2*2)+(K20*1*2) -> 0
A21: Czech Republic (91) | B21: Czech Republic | C21: =MATCH(Events!B21,'Medal Count'!C:C,0) -> 23 | D21: 1 | E21: 0 | F21: 1 | G21: =IF(SUM((D21*3)+(E21*2)+(F21*1))>0,SUM((D21*3)+(E21*2)+(F21*1)),3) -> 4 | H21: 91 | I21: {=INDEX('Medal Count'!D:D,Events!$C21)} -> 1 | J21: {=INDEX('Medal Count'!E:E,Events!$C21)} -> 1 | K21: {=INDEX('Medal Count'!F:F,Events!$C21)} -> 0 | L21: =SUM((I21*3)+(J21*2)+(K21*1)) -> 5 | O21: 1 | P21: 1 | U21: 1 | Y21: 1 | AB21: 1 | AD21: 1 | AH21: 1
A22: Denmark (38) | B22: Denmark | C22: =MATCH(Events!B22,'Medal Count'!C:C,0) -> 24 | G22: =IF(SUM((D22*3)+(E22*2)+(F22*1))>0,SUM((D22*3)+(E22*2)+(F22*1)),3) -> 3 | H22: 38 | I22: {=INDEX('Medal Count'!D:D,Events!$C22)} -> 0 | J22: {=INDEX('Medal Count'!E:E,Events!$C22)} -> 0 | K22: {=INDEX('Medal Count'!F:F,Events!$C22)} -> 0 | L22: =(I22*3*2)+(J22*2*2)+(K22*1*2) -> 0 | U22: 1
A23: Ecuador (1) | B23: Ecuador | C23: =MATCH(Events!B23,'Medal Count'!C:C,0) -> 25 | G23: =IF(SUM((D23*3)+(E23*2)+(F23*1))>0,SUM((D23*3)+(E23*2)+(F23*1)),3) -> 3 | H23: 1 | I23: {=INDEX('Medal Count'!D:D,Events!$C23)} -> 0 | J23: {=INDEX('Medal Count'!E:E,Events!$C23)} -> 0 | K23: {=INDEX('Medal Count'!F:F,Events!$C23)} -> 0 | L23: =(I23*3*2)+(J23*2*2)+(K23*1*2) -> 0
A24: Eritrea (1) | B24: Eritrea | C24: =MATCH(Events!B24,'Medal Count'!C:C,0) -> 26 | G24: =IF(SUM((D24*3)+(E24*2)+(F24*1))>0,SUM((D24*3)+(E24*2)+(F24*1)),3) -> 3 | H24: 1 | I24: {=INDEX('Medal Count'!D:D,Events!$C24)} -> 0 | J24: {=INDEX('Medal Count'!E:E,Events!$C24)} -> 0 | K24: {=INDEX('Medal Count'!F:F,Events!$C24)} -> 0 | L24: =(I24*3*2)+(J24*2*2)+(K24*1*2) -> 0
A25: Estonia (23) | B25: Estonia | C25: =MATCH(Events!B25,'Medal Count'!C:C,0) -> 27 | D25: 0 | E25: 0 | F25: 1 | G25: =IF(SUM((D25*3)+(E25*2)+(F25*1))>0,SUM((D25*3)+(E25*2)+(F25*1)),3) -> 1 | H25: 23 | I25: {=INDEX('Medal Count'!D:D,Events!$C25)} -> 0 | J25: {=INDEX('Medal Count'!E:E,Events!$C25)} -> 0 | K25: {=INDEX('Medal Count'!F:F,Events!$C25)} -> 0 | L25: =SUM((I25*3)+(J25*2)+(K25*1)) -> 0 | Q25: 1 | R25: 1 | T25: 1 | Y25: 1 | Z25: 1
A26: Finland (78) | B26: Finland | C26: =MATCH(Events!B26,'Medal Count'!C:C,0) -> 28 | D26: 2 | E26: 2 | F26: 4 | G26: =IF(SUM((D26*3)+(E26*2)+(F26*1))>0,SUM((D26*3)+(E26*2)+(F26*1)),3) -> 14 | H26: 78 | I26: {=INDEX('Medal Count'!D:D,Events!$C26)} -> 0 | J26: {=INDEX('Medal Count'!E:E,Events!$C26)} -> 0 | K26: {=INDEX('Medal Count'!F:F,Events!$C26)} -> 1 | L26: =SUM((I26*3)+(J26*2)+(K26*1)) -> 1 | O26: 1 | T26: 1 | X26: 1 | Y26: 1 | AG26: 1
A27: France (99) | B27: France | C27: =MATCH(Events!B27,'Medal Count'!C:C,0) -> 29 | D27: 5 | E27: 7 | F27: 2 | G27: =IF(SUM((D27*3)+(E27*2)+(F27*1))>0,SUM((D27*3)+(E27*2)+(F27*1)),3) -> 31 | H27: 99 | I27: {=INDEX('Medal Count'!D:D,Events!$C27)} -> 1 | J27: {=INDEX('Medal Count'!E:E,Events!$C27)} -> 2 | K27: {=INDEX('Medal Count'!F:F,Events!$C27)} -> 0 | L27: =SUM((I27*3)+(J27*2)+(K27*1)) -> 7 | N27: 1 | X27: 1
A28: Georgia (8) | B28: Georgia | C28: =MATCH(Events!B28,'Medal Count'!C:C,0) -> 30 | G28: =IF(SUM((D28*3)+(E28*2)+(F28*1))>0,SUM((D28*3)+(E28*2)+(F28*1)),3) -> 3 | H28: 8 | I28: {=INDEX('Medal Count'!D:D,Events!$C28)} -> 0 | J28: {=INDEX('Medal Count'!E:E,Events!$C28)} -> 0 | K28: {=INDEX('Medal Count'!F:F,Events!$C28)} -> 0 | L28: =(I28*3*2)+(J28*2*2)+(K28*1*2) -> 0
A29: Germany (103) | B29: Germany | C29: =MATCH(Events!B29,'Medal Count'!C:C,0) -> 31 | D29: 12 | E29: 10 | F29: 5 | G29: =IF(SUM((D29*3)+(E29*2)+(F29*1))>0,SUM((D29*3)+(E29*2)+(F29*1)),3) -> 61 | H29: 103 | I29: {=INDEX('Medal Count'!D:D,Events!$C29)} -> 3 | J29: {=INDEX('Medal Count'!E:E,Events!$C29)} -> 2 | K29: {=INDEX('Medal Count'!F:F,Events!$C29)} -> 1 | L29: =SUM((I29*3)+(J29*2)+(K29*1)) -> 14 | M29: 1 | Z29: 1 | AA29: 1 | AC29: 1
A30: Great Britain (27) | B30: Great Britain | C30: =MATCH(Events!B30,'Medal Count'!C:C,0) -> 32 | D30: 1 | E30: 1 | G30: =IF(SUM((D30*3)+(E30*2)+(F30*1))>0,SUM((D30*3)+(E30*2)+(F30*1)),3) -> 5 | H30: 27 | I30: {=INDEX('Medal Count'!D:D,Events!$C30)} -> 0 | J30: {=INDEX('Medal Count'!E:E,Events!$C30)} -> 0 | K30: {=INDEX('Medal Count'!F:F,Events!$C30)} -> 0 | L30: =SUM((I30*3)+(J30*2)+(K30*1)) -> 0 | AH30: 1
A31: Greece (5) | B31: Greece | C31: =MATCH(Events!B31,'Medal Count'!C:C,0) -> 33 | G31: =IF(SUM((D31*3)+(E31*2)+(F31*1))>0,SUM((D31*3)+(E31*2)+(F31*1)),3) -> 3 | H31: 5 | I31: {=INDEX('Medal Count'!D:D,Events!$C31)} -> 0 | J31: {=INDEX('Medal Count'!E:E,Events!$C31)} -> 0 | K31: {=INDEX('Medal Count'!F:F,Events!$C31)} -> 0 | L31: =(I31*3*2)+(J31*2*2)+(K31*1*2) -> 0
A32: Guinea-Bissau (1) | B32: Guinea-Bissau | C32: =MATCH(Events!B32,'Medal Count'!C:C,0) -> 34 | G32: =IF(SUM((D32*3)+(E32*2)+(F32*1))>0,SUM((D32*3)+(E32*2)+(F32*1)),3) -> 3 | H32: 1 | I32: {=INDEX('Medal Count'!D:D,Events!$C32)} -> 0 | J32: {=INDEX('Medal Count'!E:E,Events!$C32)} -> 0 | K32: {=INDEX('Medal Count'!F:F,Events!$C32)} -> 0 | L32: =(I32*3*2)+(J32*2*2)+(K32*1*2) -> 0
A33: Haiti (2) | B33: Haiti | C33: =MATCH(Events!B33,'Medal Count'!C:C,0) -> 35 | G33: =IF(SUM((D33*3)+(E33*2)+(F33*1))>0,SUM((D33*3)+(E33*2)+(F33*1)),3) -> 3 | H33: 2 | I33: {=INDEX('Medal Count'!D:D,Events!$C33)} -> 0 | J33: {=INDEX('Medal Count'!E:E,Events!$C33)} -> 0 | K33: {=INDEX('Medal Count'!F:F,Events!$C33)} -> 0 | L33: =(I33*3*2)+(J33*2*2)+(K33*1*2) -> 0
A34: Hong Kong (3) | B34: Hong Kong | C34: =MATCH(Events!B34,'Medal Count'!C:C,0) -> 36 | G34: =IF(SUM((D34*3)+(E34*2)+(F34*1))>0,SUM((D34*3)+(E34*2)+(F34*1)),3) -> 3 | H34: 3 | I34: {=INDEX('Medal Count'!D:D,Events!$C34)} -> 0 | J34: {=INDEX('Medal Count'!E:E,Events!$C34)} -> 0 | K34: {=INDEX('Medal Count'!F:F,Events!$C34)} -> 0 | L34: =(I34*3*2)+(J34*2*2)+(K34*1*2) -> 0
A35: Hungary (16) | B35: Hungary | C35: =MATCH(Events!B35,'Medal Count'!C:C,0) -> 37 | D35: 1 | E35: 0 | F35: 2 | G35: =IF(SUM((D35*3)+(E35*2)+(F35*1))>0,SUM((D35*3)+(E35*2)+(F35*1)),3) -> 5 | H35: 16 | I35: {=INDEX('Medal Count'!D:D,Events!$C35)} -> 0 | J35: {=INDEX('Medal Count'!E:E,Events!$C35)} -> 0 | K35: {=INDEX('Medal Count'!F:F,Events!$C35)} -> 0 | L35: =SUM((I35*3)+(J35*2)+(K35*1)) -> 0 | AF35: 1
A36: Iceland (4) | B36: Iceland | C36: =MATCH(Events!B36,'Medal Count'!C:C,0) -> 38 | G36: =IF(SUM((D36*3)+(E36*2)+(F36*1))>0,SUM((D36*3)+(E36*2)+(F36*1)),3) -> 3 | H36: 4 | I36: {=INDEX('Medal Count'!D:D,Events!$C36)} -> 0 | J36: {=INDEX('Medal Count'!E:E,Events!$C36)} -> 0 | K36: {=INDEX('Medal Count'!F:F,Events!$C36)} -> 0 | L36: =(I36*3*2)+(J36*2*2)+(K36*1*2) -> 0
A37: India (2) | B37: India | C37: =MATCH(Events!B37,'Medal Count'!C:C,0) -> 39 | G37: =IF(SUM((D37*3)+(E37*2)+(F37*1))>0,SUM((D37*3)+(E37*2)+(F37*1)),3) -> 3 | H37: 2 | I37: {=INDEX('Medal Count'!D:D,Events!$C37)} -> 0 | J37: {=INDEX('Medal Count'!E:E,Events!$C37)} -> 0 | K37: {=INDEX('Medal Count'!F:F,Events!$C37)} -> 0 | L37: =(I37*3*2)+(J37*2*2)+(K37*1*2) -> 0
A38: Individual Neutral Athletes (15) | B38: Individual Neutral Athletes | C38: =MATCH(Events!B38,'Medal Count'!C:C,0) -> 98 | G38: =IF(SUM((D38*3)+(E38*2)+(F38*1))>0,SUM((D38*3)+(E38*2)+(F38*1)),3) -> 3 | H38: 15 | I38: {=INDEX('Medal Count'!D:D,Events!$C38)} -> 0 | J38: {=INDEX('Medal Count'!E:E,Events!$C38)} -> 0 | K38: {=INDEX('Medal Count'!F:F,Events!$C38)} -> 0 | L38: =(I38*3*2)+(J38*2*2)+(K38*1*2) -> 0 | N38: 1 | Q38: 1
A39: Iran (4) | B39: Iran | C39: =MATCH(Events!B39,'Medal Count'!C:C,0) -> 40 | G39: =IF(SUM((D39*3)+(E39*2)+(F39*1))>0,SUM((D39*3)+(E39*2)+(F39*1)),3) -> 3 | H39: 4 | I39: {=INDEX('Medal Count'!D:D,Events!$C39)} -> 0 | J39: {=INDEX('Medal Count'!E:E,Events!$C39)} -> 0 | K39: {=INDEX('Medal Count'!F:F,Events!$C39)} -> 0 | L39: =(I39*3*2)+(J39*2*2)+(K39*1*2) -> 0
A40: Ireland (4) | B40: Ireland | C40: =MATCH(Events!B40,'Medal Count'!C:C,0) -> 41 | G40: =IF(SUM((D40*3)+(E40*2)+(F40*1))>0,SUM((D40*3)+(E40*2)+(F40*1)),3) -> 3 | H40: 4 | I40: {=INDEX('Medal Count'!D:D,Events!$C40)} -> 0 | J40: {=INDEX('Medal Count'!E:E,Events!$C40)} -> 0 | K40: {=INDEX('Medal Count'!F:F,Events!$C40)} -> 0 | L40: =(I40*3*2)+(J40*2*2)+(K40*1*2) -> 0
...

Sheet Medal Count
B1: Placement | C1: Country | D1: Gold Medals | E1: Silver Medals | F1: Bronze Medals | G1: Total Medals | H1: Medals/M | I1: Medals GDP
B3: – | C3: Albania | D3: 0 | E3: 0 | F3: 0 | G3: 0 | H3: 0 | I3: 0
B4: – | C4: Andorra | D4: 0 | E4: 0 | F4: 0 | G4: 0 | H4: 0 | I4: 0
B5: – | C5: Argentina | D5: 0 | E5: 0 | F5: 0 | G5: 0 | H5: 0 | I5: 0
B6: – | C6: Armenia | D6: 0 | E6: 0 | F6: 0 | G6: 0 | H6: 0 | I6: 0
B7: – | C7: Australia | D7: 0 | E7: 0 | F7: 0 | G7: 0 | H7: 0 | I7: 0
B8: 6 | C8: Austria | D8: 2 | E8: 4 | F8: 0 | G8: 6 | H8: 0.66 | I8: 0.9
B9: – | C9: Azerbaijan | D9: 0 | E9: 0 | F9: 0 | G9: 0 | H9: 0 | I9: 0
B10: 19 | C10: Belgium | D10: 0 | E10: 0 | F10: 1 | G10: 1 | H10: 0.08 | I10: 0.11
B11: – | C11: Benin | D11: 0 | E11: 0 | F11: 0 | G11: 0 | H11: 0 | I11: 0
B12: – | C12: Bolivia | D12: 0 | E12: 0 | F12: 0 | G12: 0 | H12: 0 | I12: 0
B13: – | C13: Bosnia and Herzegovina | D13: 0 | E13: 0 | F13: 0 | G13: 0 | H13: 0 | I13: 0
B14: – | C14: Brazil | D14: 0 | E14: 0 | F14: 0 | G14: 0 | H14: 0 | I14: 0
B15: 19 | C15: Bulgaria | D15: 0 | E15: 0 | F15: 1 | G15: 1 | H15: 0.16 | I15: 0.4
B16: 13 | C16: Canada | D16: 0 | E16: 1 | F16: 2 | G16: 3 | H16: 0.07 | I16: 0.11
B17: – | C17: Chile | D17: 0 | E17: 0 | F17: 0 | G17: 0 | H17: 0 | I17: 0
B18: 14 | C18: China | D18: 0 | E18: 1 | F18: 1 | G18: 2 | H18: 0 | I18: 0.01
B19: – | C19: Chinese Taipei | D19: 0 | E19: 0 | F19: 0 | G19: 0 | H19: 0 | I19: 0
B20: – | C20: Colombia | D20: 0 | E20: 0 | F20: 0 | G20: 0 | H20: 0 | I20: 0
B21: – | C21: Croatia | D21: 0 | E21: 0 | F21: 0 | G21: 0 | H21: 0 | I21: 0
B22: – | C22: Cyprus | D22: 0 | E22: 0 | F22: 0 | G22: 0 | H22: 0 | I22: 0
B23: 10 | C23: Czech Republic | D23: 1 | E23: 1 | F23: 0 | G23: 2 | H23: 0.18 | I23: 0.32
B24: – | C24: Denmark | D24: 0 | E24: 0 | F24: 0 | G24: 0 | H24: 0 | I24: 0
B25: – | C25: Ecuador | D25: 0 | E25: 0 | F25: 0 | G25: 0 | H25: 0 | I25: 0
B26: – | C26: Eritrea | D26: 0 | E26: 0 | F26: 0 | G26: 0 | H26: 0 | I26: 0
B27: – | C27: Estonia | D27: 0 | E27: 0 | F27: 0 | G27: 0 | H27: 0 | I27: 0
B28: 19 | C28: Finland | D28: 0 | E28: 0 | F28: 1 | G28: 1 | H28: 0.18 | I28: 0.28
B29: 9 | C29: France | D29: 1 | E29: 2 | F29: 0 | G29: 3 | H29: 0.04 | I29: 0.07
B30: – | C30: Georgia | D30: 0 | E30: 0 | F30: 0 | G30: 0 | H30: 0 | I30: 0
B31: 3 | C31: Germany | D31: 3 | E31: 2 | F31: 1 | G31: 6 | H31: 0.07 | I31: 0.1
B32: – | C32: Great Britain | D32: 0 | E32: 0 | F32: 0 | G32: 0 | H32: 0 | I32: 0
B33: – | C33: Greece | D33: 0 | E33: 0 | F33: 0 | G33: 0 | H33: 0 | I33: 0
B34: – | C34: Guinea-Bissau | D34: 0 | E34: 0 | F34: 0 | G34: 0 | H34: 0 | I34: 0
B35: – | C35: Haiti | D35: 0 | E35: 0 | F35: 0 | G35: 0 | H35: 0 | I35: 0
B36: – | C36: Hong Kong | D36: 0 | E36: 0 | F36: 0 | G36: 0 | H36: 0 | I36: 0
B37: – | C37: Hungary | D37: 0 | E37: 0 | F37: 0 | G37: 0 | H37: 0 | I37: 0
B38: – | C38: Iceland | D38: 0 | E38: 0 | F38: 0 | G38: 0 | H38: 0 | I38: 0
B39: – | C39: India | D39: 0 | E39: 0 | F39: 0 | G39: 0 | H39: 0 | I39: 0
B40: – | C40: Iran | D40: 0 | E40: 0 | F40: 0 | G40: 0 | H40: 0 | I40: 0
B41: – | C41: Ireland | D41: 0 | E41: 0 | F41: 0 | G41: 0 | H41: 0 | I41: 0
...

Sheet participants
A1: Participants
A2: Mansell 1 | B2: paid
A3: Mansell 2 | B3: paid
A4: Cory | B4: paid
A5: amanda | B5: paid
A6: josh | B6: paid
A7: Fader | B7: paid
A8: Bill
A9: kurt heidl | B9: paid
A10: Ryley | B10: paid
A11: Colby | B11: paid
A12: Richard | B12: paid
A13: Neigem | B13: paid
A14: Rhett
A15: wagner | B15: paid
A16: Jonah | B16: paid
A17: huebner | B17: paid
A18: Pam | B18: paid
A19: Pam | B19: paid
A20: evan | B20: paid
A21: evan | B21: paid
A22: Tiffany | B22: paid
A23: Grace | B23: paid
A24: ian | B24: paid
